I'm sorry, but an uncaught exception occurred.

While running game code:
  File "game/script.rpy", line 51, in script call
    call intro from _call_intro
  File "game/story/intro.rpy", line 196, in script
    if fail_t:
  File "game/story/intro.rpy", line 196, in <module>
    if fail_t:
NameError: name 'fail_t' is not defined

-- Full Traceback ------------------------------------------------------------

Full traceback:
  File "game/script.rpy", line 51, in script call
    call intro from _call_intro
  File "game/story/intro.rpy", line 196, in script
    if fail_t:
  File "D:\games\renpy-6.99.4-sdk\renpy-6.99.12.4-sdk\renpy\ast.py", line 1749, in execute
    if renpy.python.py_eval(condition):
  File "D:\games\renpy-6.99.4-sdk\renpy-6.99.12.4-sdk\renpy\python.py", line 1944, in py_eval
    return py_eval_bytecode(code, globals, locals)
  File "D:\games\renpy-6.99.4-sdk\renpy-6.99.12.4-sdk\renpy\python.py", line 1937, in py_eval_bytecode
    return eval(bytecode, globals, locals)
  File "game/story/intro.rpy", line 196, in <module>
    if fail_t:
NameError: name 'fail_t' is not defined

Windows-8-6.2.9200
Ren'Py 7.1.0.882
AlchemisGeneticus 1.0
Mon Oct 15 14:11:15 2018
